2024-03-26 11:58:55,171 DEBUG urllib3.connectionpool uWSGIWorker2Core0 : Starting new HTTP connection (1): datahub.utm.csic.es:80
2024-03-26 11:58:55,232 DEBUG urllib3.connectionpool uWSGIWorker2Core0 : http://datahub.utm.csic.es:80 "GET /ws/getBBox/?id=hes20231106 HTTP/1.1" 200 1
2024-03-26 12:11:51,813 INFO root uWSGIWorker5Core0 : JSON data saved successfully
2024-03-26 12:11:55,138 DEBUG urllib3.connectionpool uWSGIWorker5Core0 : Starting new HTTP connection (1): datahub.utm.csic.es:80
2024-03-26 12:11:55,170 DEBUG urllib3.connectionpool uWSGIWorker5Core0 : http://datahub.utm.csic.es:80 "GET /ws/getBBox/?id=sdg20240115 HTTP/1.1" 200 50
2024-03-26 12:14:58,148 INFO root uWSGIWorker5Core0 : JSON data saved successfully
2024-03-26 12:16:33,474 ERROR portfo uWSGIWorker2Core0 : Exception on /upload_json [POST]
Traceback (most recent call last):
  File "/home/utm/portfo/venv/lib/python3.10/site-packages/flask/app.py", line 1463, in wsgi_app
    response = self.full_dispatch_request()
  File "/home/utm/portfo/venv/lib/python3.10/site-packages/flask/app.py", line 872, in full_dispatch_request
    rv = self.handle_user_exception(e)
  File "/home/utm/portfo/venv/lib/python3.10/site-packages/flask_cors/extension.py", line 176, in wrapped_function
    return cors_after_request(app.make_response(f(*args, **kwargs)))
  File "/home/utm/portfo/venv/lib/python3.10/site-packages/flask/app.py", line 870, in full_dispatch_request
    rv = self.dispatch_request()
  File "/home/utm/portfo/venv/lib/python3.10/site-packages/flask/app.py", line 855, in dispatch_request
    return self.ensure_sync(self.view_functions[rule.endpoint])(**view_args)  # type: ignore[no-any-return]
  File "/home/utm/portfo/./portfo.py", line 330, in upload_json
    save_json_to_file(json_data, filename)
  File "/home/utm/portfo/./portfo.py", line 309, in save_json_to_file
    file_path = os.path.join(directory, filename)
  File "/usr/lib/python3.10/posixpath.py", line 90, in join
    genericpath._check_arg_types('join', a, *p)
  File "/usr/lib/python3.10/genericpath.py", line 152, in _check_arg_types
    raise TypeError(f'{funcname}() argument must be str, bytes, or '
TypeError: join() argument must be str, bytes, or os.PathLike object, not 'NoneType'
2024-03-26 12:21:07,882 DEBUG urllib3.connectionpool uWSGIWorker5Core0 : Starting new HTTP connection (1): datahub.utm.csic.es:80
2024-03-26 12:21:07,915 DEBUG urllib3.connectionpool uWSGIWorker5Core0 : http://datahub.utm.csic.es:80 "GET /ws/getBBox/?id=sdg20240115 HTTP/1.1" 200 50
2024-03-27 07:47:44,094 ERROR portfo uWSGIWorker3Core0 : Exception on /upload_json [POST]
Traceback (most recent call last):
  File "/home/utm/portfo/venv/lib/python3.10/site-packages/flask/app.py", line 1463, in wsgi_app
    response = self.full_dispatch_request()
  File "/home/utm/portfo/venv/lib/python3.10/site-packages/flask/app.py", line 872, in full_dispatch_request
    rv = self.handle_user_exception(e)
  File "/home/utm/portfo/venv/lib/python3.10/site-packages/flask_cors/extension.py", line 176, in wrapped_function
    return cors_after_request(app.make_response(f(*args, **kwargs)))
  File "/home/utm/portfo/venv/lib/python3.10/site-packages/flask/app.py", line 870, in full_dispatch_request
    rv = self.dispatch_request()
  File "/home/utm/portfo/venv/lib/python3.10/site-packages/flask/app.py", line 855, in dispatch_request
    return self.ensure_sync(self.view_functions[rule.endpoint])(**view_args)  # type: ignore[no-any-return]
  File "/home/utm/portfo/./portfo.py", line 333, in upload_json
    save_json_to_file(json_data, filename)
  File "/home/utm/portfo/./portfo.py", line 323, in save_json_to_file
    with open('jsonfile.json', encoding='utf-8') as inputfile:
FileNotFoundError: [Errno 2] No such file or directory: 'jsonfile.json'
2024-03-27 07:49:07,713 ERROR portfo uWSGIWorker2Core0 : Exception on /upload_json [POST]
Traceback (most recent call last):
  File "/home/utm/portfo/venv/lib/python3.10/site-packages/flask/app.py", line 1463, in wsgi_app
    response = self.full_dispatch_request()
  File "/home/utm/portfo/venv/lib/python3.10/site-packages/flask/app.py", line 872, in full_dispatch_request
    rv = self.handle_user_exception(e)
  File "/home/utm/portfo/venv/lib/python3.10/site-packages/flask_cors/extension.py", line 176, in wrapped_function
    return cors_after_request(app.make_response(f(*args, **kwargs)))
  File "/home/utm/portfo/venv/lib/python3.10/site-packages/flask/app.py", line 870, in full_dispatch_request
    rv = self.dispatch_request()
  File "/home/utm/portfo/venv/lib/python3.10/site-packages/flask/app.py", line 855, in dispatch_request
    return self.ensure_sync(self.view_functions[rule.endpoint])(**view_args)  # type: ignore[no-any-return]
  File "/home/utm/portfo/./portfo.py", line 333, in upload_json
    save_json_to_file(json_data, filename)
  File "/home/utm/portfo/./portfo.py", line 324, in save_json_to_file
    df = pd.read_json(inputfile)
  File "/home/utm/portfo/venv/lib/python3.10/site-packages/pandas/io/json/_json.py", line 815, in read_json
    return json_reader.read()
  File "/home/utm/portfo/venv/lib/python3.10/site-packages/pandas/io/json/_json.py", line 1025, in read
    obj = self._get_object_parser(self.data)
  File "/home/utm/portfo/venv/lib/python3.10/site-packages/pandas/io/json/_json.py", line 1051, in _get_object_parser
    obj = FrameParser(json, **kwargs).parse()
  File "/home/utm/portfo/venv/lib/python3.10/site-packages/pandas/io/json/_json.py", line 1187, in parse
    self._parse()
  File "/home/utm/portfo/venv/lib/python3.10/site-packages/pandas/io/json/_json.py", line 1399, in _parse
    self.obj = DataFrame(
  File "/home/utm/portfo/venv/lib/python3.10/site-packages/pandas/core/frame.py", line 875, in __init__
    raise ValueError("DataFrame constructor not properly called!")
ValueError: DataFrame constructor not properly called!
2024-03-27 08:26:09,797 ERROR portfo uWSGIWorker5Core0 : Exception on /upload_json [POST]
Traceback (most recent call last):
  File "/home/utm/portfo/venv/lib/python3.10/site-packages/flask/app.py", line 1463, in wsgi_app
    response = self.full_dispatch_request()
  File "/home/utm/portfo/venv/lib/python3.10/site-packages/flask/app.py", line 872, in full_dispatch_request
    rv = self.handle_user_exception(e)
  File "/home/utm/portfo/venv/lib/python3.10/site-packages/flask_cors/extension.py", line 176, in wrapped_function
    return cors_after_request(app.make_response(f(*args, **kwargs)))
  File "/home/utm/portfo/venv/lib/python3.10/site-packages/flask/app.py", line 870, in full_dispatch_request
    rv = self.dispatch_request()
  File "/home/utm/portfo/venv/lib/python3.10/site-packages/flask/app.py", line 855, in dispatch_request
    return self.ensure_sync(self.view_functions[rule.endpoint])(**view_args)  # type: ignore[no-any-return]
  File "/home/utm/portfo/./portfo.py", line 333, in upload_json
    return jsonify({'message': 'JSON data saved successfully'})
  File "/home/utm/portfo/./portfo.py", line 324, in save_json_to_file
  File "/home/utm/portfo/venv/lib/python3.10/site-packages/pandas/io/json/_json.py", line 815, in read_json
    return json_reader.read()
  File "/home/utm/portfo/venv/lib/python3.10/site-packages/pandas/io/json/_json.py", line 1025, in read
    obj = self._get_object_parser(self.data)
  File "/home/utm/portfo/venv/lib/python3.10/site-packages/pandas/io/json/_json.py", line 1051, in _get_object_parser
    obj = FrameParser(json, **kwargs).parse()
  File "/home/utm/portfo/venv/lib/python3.10/site-packages/pandas/io/json/_json.py", line 1187, in parse
    self._parse()
  File "/home/utm/portfo/venv/lib/python3.10/site-packages/pandas/io/json/_json.py", line 1399, in _parse
    self.obj = DataFrame(
  File "/home/utm/portfo/venv/lib/python3.10/site-packages/pandas/core/frame.py", line 875, in __init__
    raise ValueError("DataFrame constructor not properly called!")
ValueError: DataFrame constructor not properly called!
2024-03-27 08:27:17,964 INFO root uWSGIWorker3Core0 : JSON data saved successfully
2024-03-27 09:06:12,969 INFO root uWSGIWorker2Core0 : JSON data saved successfully
2024-03-27 09:06:18,371 ERROR portfo uWSGIWorker1Core0 : Exception on /download_step1 [POST]
Traceback (most recent call last):
  File "/home/utm/portfo/venv/lib/python3.10/site-packages/flask/app.py", line 1463, in wsgi_app
    response = self.full_dispatch_request()
  File "/home/utm/portfo/venv/lib/python3.10/site-packages/flask/app.py", line 872, in full_dispatch_request
    rv = self.handle_user_exception(e)
  File "/home/utm/portfo/venv/lib/python3.10/site-packages/flask_cors/extension.py", line 176, in wrapped_function
    return cors_after_request(app.make_response(f(*args, **kwargs)))
  File "/home/utm/portfo/venv/lib/python3.10/site-packages/flask/app.py", line 870, in full_dispatch_request
    rv = self.dispatch_request()
  File "/home/utm/portfo/venv/lib/python3.10/site-packages/flask/app.py", line 855, in dispatch_request
    return self.ensure_sync(self.view_functions[rule.endpoint])(**view_args)  # type: ignore[no-any-return]
  File "/home/utm/portfo/./portfo.py", line 226, in download_step1
    with open('uploaded_data.json', encoding='utf-8') as inputfile:
FileNotFoundError: [Errno 2] No such file or directory: 'uploaded_data.json'
2024-03-27 09:06:18,520 ERROR portfo uWSGIWorker5Core0 : Exception on /favicon.ico [GET]
Traceback (most recent call last):
  File "/home/utm/portfo/venv/lib/python3.10/site-packages/flask/app.py", line 1463, in wsgi_app
    response = self.full_dispatch_request()
  File "/home/utm/portfo/venv/lib/python3.10/site-packages/flask/app.py", line 872, in full_dispatch_request
    rv = self.handle_user_exception(e)
  File "/home/utm/portfo/venv/lib/python3.10/site-packages/flask_cors/extension.py", line 176, in wrapped_function
    return cors_after_request(app.make_response(f(*args, **kwargs)))
  File "/home/utm/portfo/venv/lib/python3.10/site-packages/flask/app.py", line 870, in full_dispatch_request
    rv = self.dispatch_request()
  File "/home/utm/portfo/venv/lib/python3.10/site-packages/flask/app.py", line 855, in dispatch_request
    return self.ensure_sync(self.view_functions[rule.endpoint])(**view_args)  # type: ignore[no-any-return]
  File "/home/utm/portfo/./portfo.py", line 61, in html_page
    return render_template(page_name)
  File "/home/utm/portfo/venv/lib/python3.10/site-packages/flask/templating.py", line 149, in render_template
    template = app.jinja_env.get_or_select_template(template_name_or_list)
  File "/home/utm/portfo/venv/lib/python3.10/site-packages/jinja2/environment.py", line 1081, in get_or_select_template
    return self.get_template(template_name_or_list, parent, globals)
  File "/home/utm/portfo/venv/lib/python3.10/site-packages/jinja2/environment.py", line 1010, in get_template
    return self._load_template(name, globals)
  File "/home/utm/portfo/venv/lib/python3.10/site-packages/jinja2/environment.py", line 969, in _load_template
    template = self.loader.load(self, name, self.make_globals(globals))
  File "/home/utm/portfo/venv/lib/python3.10/site-packages/jinja2/loaders.py", line 125, in load
    source, filename, uptodate = self.get_source(environment, name)
  File "/home/utm/portfo/venv/lib/python3.10/site-packages/flask/templating.py", line 65, in get_source
    return self._get_source_fast(environment, template)
  File "/home/utm/portfo/venv/lib/python3.10/site-packages/flask/templating.py", line 99, in _get_source_fast
    raise TemplateNotFound(template)
jinja2.exceptions.TemplateNotFound: favicon.ico
2024-03-27 09:10:24,761 INFO root uWSGIWorker3Core0 : JSON data saved successfully
2024-03-27 09:10:28,662 ERROR portfo uWSGIWorker1Core0 : Exception on /download_step1 [POST]
Traceback (most recent call last):
  File "/home/utm/portfo/venv/lib/python3.10/site-packages/flask/app.py", line 1463, in wsgi_app
    response = self.full_dispatch_request()
  File "/home/utm/portfo/venv/lib/python3.10/site-packages/flask/app.py", line 872, in full_dispatch_request
    rv = self.handle_user_exception(e)
  File "/home/utm/portfo/venv/lib/python3.10/site-packages/flask_cors/extension.py", line 176, in wrapped_function
    return cors_after_request(app.make_response(f(*args, **kwargs)))
  File "/home/utm/portfo/venv/lib/python3.10/site-packages/flask/app.py", line 870, in full_dispatch_request
    rv = self.dispatch_request()
  File "/home/utm/portfo/venv/lib/python3.10/site-packages/flask/app.py", line 855, in dispatch_request
    return self.ensure_sync(self.view_functions[rule.endpoint])(**view_args)  # type: ignore[no-any-return]
  File "/home/utm/portfo/./portfo.py", line 226, in download_step1
    with open('static/uploaded_data.json', encoding='utf-8') as inputfile:
FileNotFoundError: [Errno 2] No such file or directory: 'static/uploaded_data.json'
2024-03-27 09:10:28,870 ERROR portfo uWSGIWorker4Core0 : Exception on /favicon.ico [GET]
Traceback (most recent call last):
  File "/home/utm/portfo/venv/lib/python3.10/site-packages/flask/app.py", line 1463, in wsgi_app
    response = self.full_dispatch_request()
  File "/home/utm/portfo/venv/lib/python3.10/site-packages/flask/app.py", line 872, in full_dispatch_request
    rv = self.handle_user_exception(e)
  File "/home/utm/portfo/venv/lib/python3.10/site-packages/flask_cors/extension.py", line 176, in wrapped_function
    return cors_after_request(app.make_response(f(*args, **kwargs)))
  File "/home/utm/portfo/venv/lib/python3.10/site-packages/flask/app.py", line 870, in full_dispatch_request
    rv = self.dispatch_request()
  File "/home/utm/portfo/venv/lib/python3.10/site-packages/flask/app.py", line 855, in dispatch_request
    return self.ensure_sync(self.view_functions[rule.endpoint])(**view_args)  # type: ignore[no-any-return]
  File "/home/utm/portfo/./portfo.py", line 61, in html_page
    return render_template(page_name)
  File "/home/utm/portfo/venv/lib/python3.10/site-packages/flask/templating.py", line 149, in render_template
    template = app.jinja_env.get_or_select_template(template_name_or_list)
  File "/home/utm/portfo/venv/lib/python3.10/site-packages/jinja2/environment.py", line 1081, in get_or_select_template
    return self.get_template(template_name_or_list, parent, globals)
  File "/home/utm/portfo/venv/lib/python3.10/site-packages/jinja2/environment.py", line 1010, in get_template
    return self._load_template(name, globals)
  File "/home/utm/portfo/venv/lib/python3.10/site-packages/jinja2/environment.py", line 969, in _load_template
    template = self.loader.load(self, name, self.make_globals(globals))
  File "/home/utm/portfo/venv/lib/python3.10/site-packages/jinja2/loaders.py", line 125, in load
    source, filename, uptodate = self.get_source(environment, name)
  File "/home/utm/portfo/venv/lib/python3.10/site-packages/flask/templating.py", line 65, in get_source
    return self._get_source_fast(environment, template)
  File "/home/utm/portfo/venv/lib/python3.10/site-packages/flask/templating.py", line 99, in _get_source_fast
    raise TemplateNotFound(template)
jinja2.exceptions.TemplateNotFound: favicon.ico
2024-03-27 09:11:52,382 ERROR portfo uWSGIWorker4Core0 : Exception on /favicon.ico [GET]
Traceback (most recent call last):
  File "/home/utm/portfo/venv/lib/python3.10/site-packages/flask/app.py", line 1463, in wsgi_app
    response = self.full_dispatch_request()
  File "/home/utm/portfo/venv/lib/python3.10/site-packages/flask/app.py", line 872, in full_dispatch_request
    rv = self.handle_user_exception(e)
  File "/home/utm/portfo/venv/lib/python3.10/site-packages/flask_cors/extension.py", line 176, in wrapped_function
    return cors_after_request(app.make_response(f(*args, **kwargs)))
  File "/home/utm/portfo/venv/lib/python3.10/site-packages/flask/app.py", line 870, in full_dispatch_request
    rv = self.dispatch_request()
  File "/home/utm/portfo/venv/lib/python3.10/site-packages/flask/app.py", line 855, in dispatch_request
    return self.ensure_sync(self.view_functions[rule.endpoint])(**view_args)  # type: ignore[no-any-return]
  File "/home/utm/portfo/./portfo.py", line 61, in html_page
    return render_template(page_name)
  File "/home/utm/portfo/venv/lib/python3.10/site-packages/flask/templating.py", line 149, in render_template
    template = app.jinja_env.get_or_select_template(template_name_or_list)
  File "/home/utm/portfo/venv/lib/python3.10/site-packages/jinja2/environment.py", line 1081, in get_or_select_template
    return self.get_template(template_name_or_list, parent, globals)
  File "/home/utm/portfo/venv/lib/python3.10/site-packages/jinja2/environment.py", line 1010, in get_template
    return self._load_template(name, globals)
  File "/home/utm/portfo/venv/lib/python3.10/site-packages/jinja2/environment.py", line 969, in _load_template
    template = self.loader.load(self, name, self.make_globals(globals))
  File "/home/utm/portfo/venv/lib/python3.10/site-packages/jinja2/loaders.py", line 125, in load
    source, filename, uptodate = self.get_source(environment, name)
  File "/home/utm/portfo/venv/lib/python3.10/site-packages/flask/templating.py", line 65, in get_source
    return self._get_source_fast(environment, template)
  File "/home/utm/portfo/venv/lib/python3.10/site-packages/flask/templating.py", line 99, in _get_source_fast
    raise TemplateNotFound(template)
jinja2.exceptions.TemplateNotFound: favicon.ico
2024-03-27 09:12:08,182 ERROR portfo uWSGIWorker5Core0 : Exception on /static [GET]
Traceback (most recent call last):
  File "/home/utm/portfo/venv/lib/python3.10/site-packages/flask/app.py", line 1463, in wsgi_app
    response = self.full_dispatch_request()
  File "/home/utm/portfo/venv/lib/python3.10/site-packages/flask/app.py", line 872, in full_dispatch_request
    rv = self.handle_user_exception(e)
  File "/home/utm/portfo/venv/lib/python3.10/site-packages/flask_cors/extension.py", line 176, in wrapped_function
    return cors_after_request(app.make_response(f(*args, **kwargs)))
  File "/home/utm/portfo/venv/lib/python3.10/site-packages/flask/app.py", line 870, in full_dispatch_request
    rv = self.dispatch_request()
  File "/home/utm/portfo/venv/lib/python3.10/site-packages/flask/app.py", line 855, in dispatch_request
    return self.ensure_sync(self.view_functions[rule.endpoint])(**view_args)  # type: ignore[no-any-return]
  File "/home/utm/portfo/./portfo.py", line 61, in html_page
    return render_template(page_name)
  File "/home/utm/portfo/venv/lib/python3.10/site-packages/flask/templating.py", line 149, in render_template
    template = app.jinja_env.get_or_select_template(template_name_or_list)
  File "/home/utm/portfo/venv/lib/python3.10/site-packages/jinja2/environment.py", line 1081, in get_or_select_template
    return self.get_template(template_name_or_list, parent, globals)
  File "/home/utm/portfo/venv/lib/python3.10/site-packages/jinja2/environment.py", line 1010, in get_template
    return self._load_template(name, globals)
  File "/home/utm/portfo/venv/lib/python3.10/site-packages/jinja2/environment.py", line 969, in _load_template
    template = self.loader.load(self, name, self.make_globals(globals))
  File "/home/utm/portfo/venv/lib/python3.10/site-packages/jinja2/loaders.py", line 125, in load
    source, filename, uptodate = self.get_source(environment, name)
  File "/home/utm/portfo/venv/lib/python3.10/site-packages/flask/templating.py", line 65, in get_source
    return self._get_source_fast(environment, template)
  File "/home/utm/portfo/venv/lib/python3.10/site-packages/flask/templating.py", line 99, in _get_source_fast
    raise TemplateNotFound(template)
jinja2.exceptions.TemplateNotFound: static
2024-03-27 09:12:08,395 ERROR portfo uWSGIWorker4Core0 : Exception on /favicon.ico [GET]
Traceback (most recent call last):
  File "/home/utm/portfo/venv/lib/python3.10/site-packages/flask/app.py", line 1463, in wsgi_app
    response = self.full_dispatch_request()
  File "/home/utm/portfo/venv/lib/python3.10/site-packages/flask/app.py", line 872, in full_dispatch_request
    rv = self.handle_user_exception(e)
  File "/home/utm/portfo/venv/lib/python3.10/site-packages/flask_cors/extension.py", line 176, in wrapped_function
    return cors_after_request(app.make_response(f(*args, **kwargs)))
  File "/home/utm/portfo/venv/lib/python3.10/site-packages/flask/app.py", line 870, in full_dispatch_request
    rv = self.dispatch_request()
  File "/home/utm/portfo/venv/lib/python3.10/site-packages/flask/app.py", line 855, in dispatch_request
    return self.ensure_sync(self.view_functions[rule.endpoint])(**view_args)  # type: ignore[no-any-return]
  File "/home/utm/portfo/./portfo.py", line 61, in html_page
    return render_template(page_name)
  File "/home/utm/portfo/venv/lib/python3.10/site-packages/flask/templating.py", line 149, in render_template
    template = app.jinja_env.get_or_select_template(template_name_or_list)
  File "/home/utm/portfo/venv/lib/python3.10/site-packages/jinja2/environment.py", line 1081, in get_or_select_template
    return self.get_template(template_name_or_list, parent, globals)
  File "/home/utm/portfo/venv/lib/python3.10/site-packages/jinja2/environment.py", line 1010, in get_template
    return self._load_template(name, globals)
  File "/home/utm/portfo/venv/lib/python3.10/site-packages/jinja2/environment.py", line 969, in _load_template
    template = self.loader.load(self, name, self.make_globals(globals))
  File "/home/utm/portfo/venv/lib/python3.10/site-packages/jinja2/loaders.py", line 125, in load
    source, filename, uptodate = self.get_source(environment, name)
  File "/home/utm/portfo/venv/lib/python3.10/site-packages/flask/templating.py", line 65, in get_source
    return self._get_source_fast(environment, template)
  File "/home/utm/portfo/venv/lib/python3.10/site-packages/flask/templating.py", line 99, in _get_source_fast
    raise TemplateNotFound(template)
jinja2.exceptions.TemplateNotFound: favicon.ico
2024-03-27 09:13:59,328 ERROR portfo uWSGIWorker4Core0 : Exception on /favicon.ico [GET]
Traceback (most recent call last):
  File "/home/utm/portfo/venv/lib/python3.10/site-packages/flask/app.py", line 1463, in wsgi_app
    response = self.full_dispatch_request()
  File "/home/utm/portfo/venv/lib/python3.10/site-packages/flask/app.py", line 872, in full_dispatch_request
    rv = self.handle_user_exception(e)
  File "/home/utm/portfo/venv/lib/python3.10/site-packages/flask_cors/extension.py", line 176, in wrapped_function
    return cors_after_request(app.make_response(f(*args, **kwargs)))
  File "/home/utm/portfo/venv/lib/python3.10/site-packages/flask/app.py", line 870, in full_dispatch_request
    rv = self.dispatch_request()
  File "/home/utm/portfo/venv/lib/python3.10/site-packages/flask/app.py", line 855, in dispatch_request
    return self.ensure_sync(self.view_functions[rule.endpoint])(**view_args)  # type: ignore[no-any-return]
  File "/home/utm/portfo/./portfo.py", line 61, in html_page
    return render_template(page_name)
  File "/home/utm/portfo/venv/lib/python3.10/site-packages/flask/templating.py", line 149, in render_template
    template = app.jinja_env.get_or_select_template(template_name_or_list)
  File "/home/utm/portfo/venv/lib/python3.10/site-packages/jinja2/environment.py", line 1081, in get_or_select_template
    return self.get_template(template_name_or_list, parent, globals)
  File "/home/utm/portfo/venv/lib/python3.10/site-packages/jinja2/environment.py", line 1010, in get_template
    return self._load_template(name, globals)
  File "/home/utm/portfo/venv/lib/python3.10/site-packages/jinja2/environment.py", line 969, in _load_template
    template = self.loader.load(self, name, self.make_globals(globals))
  File "/home/utm/portfo/venv/lib/python3.10/site-packages/jinja2/loaders.py", line 125, in load
    source, filename, uptodate = self.get_source(environment, name)
  File "/home/utm/portfo/venv/lib/python3.10/site-packages/flask/templating.py", line 65, in get_source
    return self._get_source_fast(environment, template)
  File "/home/utm/portfo/venv/lib/python3.10/site-packages/flask/templating.py", line 99, in _get_source_fast
    raise TemplateNotFound(template)
jinja2.exceptions.TemplateNotFound: favicon.ico
2024-03-27 09:14:01,023 ERROR portfo uWSGIWorker4Core0 : Exception on /favicon.ico [GET]
Traceback (most recent call last):
  File "/home/utm/portfo/venv/lib/python3.10/site-packages/flask/app.py", line 1463, in wsgi_app
    response = self.full_dispatch_request()
  File "/home/utm/portfo/venv/lib/python3.10/site-packages/flask/app.py", line 872, in full_dispatch_request
    rv = self.handle_user_exception(e)
  File "/home/utm/portfo/venv/lib/python3.10/site-packages/flask_cors/extension.py", line 176, in wrapped_function
    return cors_after_request(app.make_response(f(*args, **kwargs)))
  File "/home/utm/portfo/venv/lib/python3.10/site-packages/flask/app.py", line 870, in full_dispatch_request
    rv = self.dispatch_request()
  File "/home/utm/portfo/venv/lib/python3.10/site-packages/flask/app.py", line 855, in dispatch_request
    return self.ensure_sync(self.view_functions[rule.endpoint])(**view_args)  # type: ignore[no-any-return]
  File "/home/utm/portfo/./portfo.py", line 61, in html_page
    return render_template(page_name)
  File "/home/utm/portfo/venv/lib/python3.10/site-packages/flask/templating.py", line 149, in render_template
    template = app.jinja_env.get_or_select_template(template_name_or_list)
  File "/home/utm/portfo/venv/lib/python3.10/site-packages/jinja2/environment.py", line 1081, in get_or_select_template
    return self.get_template(template_name_or_list, parent, globals)
  File "/home/utm/portfo/venv/lib/python3.10/site-packages/jinja2/environment.py", line 1010, in get_template
    return self._load_template(name, globals)
  File "/home/utm/portfo/venv/lib/python3.10/site-packages/jinja2/environment.py", line 969, in _load_template
    template = self.loader.load(self, name, self.make_globals(globals))
  File "/home/utm/portfo/venv/lib/python3.10/site-packages/jinja2/loaders.py", line 125, in load
    source, filename, uptodate = self.get_source(environment, name)
  File "/home/utm/portfo/venv/lib/python3.10/site-packages/flask/templating.py", line 65, in get_source
    return self._get_source_fast(environment, template)
  File "/home/utm/portfo/venv/lib/python3.10/site-packages/flask/templating.py", line 99, in _get_source_fast
    raise TemplateNotFound(template)
jinja2.exceptions.TemplateNotFound: favicon.ico
2024-03-27 09:14:09,998 ERROR portfo uWSGIWorker4Core0 : Exception on /favicon.ico [GET]
Traceback (most recent call last):
  File "/home/utm/portfo/venv/lib/python3.10/site-packages/flask/app.py", line 1463, in wsgi_app
    response = self.full_dispatch_request()
  File "/home/utm/portfo/venv/lib/python3.10/site-packages/flask/app.py", line 872, in full_dispatch_request
    rv = self.handle_user_exception(e)
  File "/home/utm/portfo/venv/lib/python3.10/site-packages/flask_cors/extension.py", line 176, in wrapped_function
    return cors_after_request(app.make_response(f(*args, **kwargs)))
  File "/home/utm/portfo/venv/lib/python3.10/site-packages/flask/app.py", line 870, in full_dispatch_request
    rv = self.dispatch_request()
  File "/home/utm/portfo/venv/lib/python3.10/site-packages/flask/app.py", line 855, in dispatch_request
    return self.ensure_sync(self.view_functions[rule.endpoint])(**view_args)  # type: ignore[no-any-return]
  File "/home/utm/portfo/./portfo.py", line 61, in html_page
    return render_template(page_name)
  File "/home/utm/portfo/venv/lib/python3.10/site-packages/flask/templating.py", line 149, in render_template
    template = app.jinja_env.get_or_select_template(template_name_or_list)
  File "/home/utm/portfo/venv/lib/python3.10/site-packages/jinja2/environment.py", line 1081, in get_or_select_template
    return self.get_template(template_name_or_list, parent, globals)
  File "/home/utm/portfo/venv/lib/python3.10/site-packages/jinja2/environment.py", line 1010, in get_template
    return self._load_template(name, globals)
  File "/home/utm/portfo/venv/lib/python3.10/site-packages/jinja2/environment.py", line 969, in _load_template
    template = self.loader.load(self, name, self.make_globals(globals))
  File "/home/utm/portfo/venv/lib/python3.10/site-packages/jinja2/loaders.py", line 125, in load
    source, filename, uptodate = self.get_source(environment, name)
  File "/home/utm/portfo/venv/lib/python3.10/site-packages/flask/templating.py", line 65, in get_source
    return self._get_source_fast(environment, template)
  File "/home/utm/portfo/venv/lib/python3.10/site-packages/flask/templating.py", line 99, in _get_source_fast
    raise TemplateNotFound(template)
jinja2.exceptions.TemplateNotFound: favicon.ico
2024-03-27 09:16:08,696 INFO root uWSGIWorker5Core0 : JSON data saved successfully
2024-03-27 09:16:12,083 ERROR portfo uWSGIWorker3Core0 : Exception on /download_step1 [POST]
Traceback (most recent call last):
  File "/home/utm/portfo/venv/lib/python3.10/site-packages/flask/app.py", line 1463, in wsgi_app
    response = self.full_dispatch_request()
  File "/home/utm/portfo/venv/lib/python3.10/site-packages/flask/app.py", line 872, in full_dispatch_request
    rv = self.handle_user_exception(e)
  File "/home/utm/portfo/venv/lib/python3.10/site-packages/flask_cors/extension.py", line 176, in wrapped_function
    return cors_after_request(app.make_response(f(*args, **kwargs)))
  File "/home/utm/portfo/venv/lib/python3.10/site-packages/flask/app.py", line 870, in full_dispatch_request
    rv = self.dispatch_request()
  File "/home/utm/portfo/venv/lib/python3.10/site-packages/flask/app.py", line 855, in dispatch_request
    return self.ensure_sync(self.view_functions[rule.endpoint])(**view_args)  # type: ignore[no-any-return]
  File "/home/utm/portfo/./portfo.py", line 226, in download_step1
    with open('http://161.111.137.92:8001/static/csv/uploaded_data.json', encoding='utf-8') as inputfile:
FileNotFoundError: [Errno 2] No such file or directory: 'http://161.111.137.92:8001/static/csv/uploaded_data.json'
2024-03-27 09:16:12,252 ERROR portfo uWSGIWorker1Core0 : Exception on /favicon.ico [GET]
Traceback (most recent call last):
  File "/home/utm/portfo/venv/lib/python3.10/site-packages/flask/app.py", line 1463, in wsgi_app
    response = self.full_dispatch_request()
  File "/home/utm/portfo/venv/lib/python3.10/site-packages/flask/app.py", line 872, in full_dispatch_request
    rv = self.handle_user_exception(e)
  File "/home/utm/portfo/venv/lib/python3.10/site-packages/flask_cors/extension.py", line 176, in wrapped_function
    return cors_after_request(app.make_response(f(*args, **kwargs)))
  File "/home/utm/portfo/venv/lib/python3.10/site-packages/flask/app.py", line 870, in full_dispatch_request
    rv = self.dispatch_request()
  File "/home/utm/portfo/venv/lib/python3.10/site-packages/flask/app.py", line 855, in dispatch_request
    return self.ensure_sync(self.view_functions[rule.endpoint])(**view_args)  # type: ignore[no-any-return]
  File "/home/utm/portfo/./portfo.py", line 61, in html_page
    return render_template(page_name)
  File "/home/utm/portfo/venv/lib/python3.10/site-packages/flask/templating.py", line 149, in render_template
    template = app.jinja_env.get_or_select_template(template_name_or_list)
  File "/home/utm/portfo/venv/lib/python3.10/site-packages/jinja2/environment.py", line 1081, in get_or_select_template
    return self.get_template(template_name_or_list, parent, globals)
  File "/home/utm/portfo/venv/lib/python3.10/site-packages/jinja2/environment.py", line 1010, in get_template
    return self._load_template(name, globals)
  File "/home/utm/portfo/venv/lib/python3.10/site-packages/jinja2/environment.py", line 969, in _load_template
    template = self.loader.load(self, name, self.make_globals(globals))
  File "/home/utm/portfo/venv/lib/python3.10/site-packages/jinja2/loaders.py", line 125, in load
    source, filename, uptodate = self.get_source(environment, name)
  File "/home/utm/portfo/venv/lib/python3.10/site-packages/flask/templating.py", line 65, in get_source
    return self._get_source_fast(environment, template)
  File "/home/utm/portfo/venv/lib/python3.10/site-packages/flask/templating.py", line 99, in _get_source_fast
    raise TemplateNotFound(template)
jinja2.exceptions.TemplateNotFound: favicon.ico
2024-03-27 09:17:46,755 ERROR portfo uWSGIWorker1Core0 : Exception on /favicon.ico [GET]
Traceback (most recent call last):
  File "/home/utm/portfo/venv/lib/python3.10/site-packages/flask/app.py", line 1463, in wsgi_app
    response = self.full_dispatch_request()
  File "/home/utm/portfo/venv/lib/python3.10/site-packages/flask/app.py", line 872, in full_dispatch_request
    rv = self.handle_user_exception(e)
  File "/home/utm/portfo/venv/lib/python3.10/site-packages/flask_cors/extension.py", line 176, in wrapped_function
    return cors_after_request(app.make_response(f(*args, **kwargs)))
  File "/home/utm/portfo/venv/lib/python3.10/site-packages/flask/app.py", line 870, in full_dispatch_request
    rv = self.dispatch_request()
  File "/home/utm/portfo/venv/lib/python3.10/site-packages/flask/app.py", line 855, in dispatch_request
    return self.ensure_sync(self.view_functions[rule.endpoint])(**view_args)  # type: ignore[no-any-return]
  File "/home/utm/portfo/./portfo.py", line 61, in html_page
    return render_template(page_name)
  File "/home/utm/portfo/venv/lib/python3.10/site-packages/flask/templating.py", line 149, in render_template
    template = app.jinja_env.get_or_select_template(template_name_or_list)
  File "/home/utm/portfo/venv/lib/python3.10/site-packages/jinja2/environment.py", line 1081, in get_or_select_template
    return self.get_template(template_name_or_list, parent, globals)
  File "/home/utm/portfo/venv/lib/python3.10/site-packages/jinja2/environment.py", line 1010, in get_template
    return self._load_template(name, globals)
  File "/home/utm/portfo/venv/lib/python3.10/site-packages/jinja2/environment.py", line 969, in _load_template
    template = self.loader.load(self, name, self.make_globals(globals))
  File "/home/utm/portfo/venv/lib/python3.10/site-packages/jinja2/loaders.py", line 125, in load
    source, filename, uptodate = self.get_source(environment, name)
  File "/home/utm/portfo/venv/lib/python3.10/site-packages/flask/templating.py", line 65, in get_source
    return self._get_source_fast(environment, template)
  File "/home/utm/portfo/venv/lib/python3.10/site-packages/flask/templating.py", line 99, in _get_source_fast
    raise TemplateNotFound(template)
jinja2.exceptions.TemplateNotFound: favicon.ico
2024-03-27 09:19:59,407 INFO root uWSGIWorker5Core0 : JSON data saved successfully
2024-03-27 09:20:03,677 ERROR portfo uWSGIWorker5Core0 : Exception on /download_step1 [POST]
Traceback (most recent call last):
  File "/home/utm/portfo/venv/lib/python3.10/site-packages/flask/app.py", line 1463, in wsgi_app
    response = self.full_dispatch_request()
  File "/home/utm/portfo/venv/lib/python3.10/site-packages/flask/app.py", line 872, in full_dispatch_request
    rv = self.handle_user_exception(e)
  File "/home/utm/portfo/venv/lib/python3.10/site-packages/flask_cors/extension.py", line 176, in wrapped_function
    return cors_after_request(app.make_response(f(*args, **kwargs)))
  File "/home/utm/portfo/venv/lib/python3.10/site-packages/flask/app.py", line 870, in full_dispatch_request
    rv = self.dispatch_request()
  File "/home/utm/portfo/venv/lib/python3.10/site-packages/flask/app.py", line 855, in dispatch_request
    return self.ensure_sync(self.view_functions[rule.endpoint])(**view_args)  # type: ignore[no-any-return]
  File "/home/utm/portfo/./portfo.py", line 224, in download_step1
    with open('http://161.111.137.92:8001/static/csv/uploaded_data.json', encoding='utf-8') as inputfile:
FileNotFoundError: [Errno 2] No such file or directory: 'http://161.111.137.92:8001/static/csv/uploaded_data.json'
2024-03-27 09:20:03,757 ERROR portfo uWSGIWorker5Core0 : Exception on /favicon.ico [GET]
Traceback (most recent call last):
  File "/home/utm/portfo/venv/lib/python3.10/site-packages/flask/app.py", line 1463, in wsgi_app
    response = self.full_dispatch_request()
  File "/home/utm/portfo/venv/lib/python3.10/site-packages/flask/app.py", line 872, in full_dispatch_request
    rv = self.handle_user_exception(e)
  File "/home/utm/portfo/venv/lib/python3.10/site-packages/flask_cors/extension.py", line 176, in wrapped_function
    return cors_after_request(app.make_response(f(*args, **kwargs)))
  File "/home/utm/portfo/venv/lib/python3.10/site-packages/flask/app.py", line 870, in full_dispatch_request
    rv = self.dispatch_request()
  File "/home/utm/portfo/venv/lib/python3.10/site-packages/flask/app.py", line 855, in dispatch_request
    return self.ensure_sync(self.view_functions[rule.endpoint])(**view_args)  # type: ignore[no-any-return]
  File "/home/utm/portfo/./portfo.py", line 61, in html_page
    return render_template(page_name)
  File "/home/utm/portfo/venv/lib/python3.10/site-packages/flask/templating.py", line 149, in render_template
    template = app.jinja_env.get_or_select_template(template_name_or_list)
  File "/home/utm/portfo/venv/lib/python3.10/site-packages/jinja2/environment.py", line 1081, in get_or_select_template
    return self.get_template(template_name_or_list, parent, globals)
  File "/home/utm/portfo/venv/lib/python3.10/site-packages/jinja2/environment.py", line 1010, in get_template
    return self._load_template(name, globals)
  File "/home/utm/portfo/venv/lib/python3.10/site-packages/jinja2/environment.py", line 969, in _load_template
    template = self.loader.load(self, name, self.make_globals(globals))
  File "/home/utm/portfo/venv/lib/python3.10/site-packages/jinja2/loaders.py", line 125, in load
    source, filename, uptodate = self.get_source(environment, name)
  File "/home/utm/portfo/venv/lib/python3.10/site-packages/flask/templating.py", line 65, in get_source
    return self._get_source_fast(environment, template)
  File "/home/utm/portfo/venv/lib/python3.10/site-packages/flask/templating.py", line 99, in _get_source_fast
    raise TemplateNotFound(template)
jinja2.exceptions.TemplateNotFound: favicon.ico
2024-03-27 09:22:44,143 INFO root uWSGIWorker2Core0 : JSON data saved successfully
2024-03-27 09:22:48,650 ERROR portfo uWSGIWorker4Core0 : Exception on /download_step1 [POST]
Traceback (most recent call last):
  File "/home/utm/portfo/venv/lib/python3.10/site-packages/flask/app.py", line 1463, in wsgi_app
    response = self.full_dispatch_request()
  File "/home/utm/portfo/venv/lib/python3.10/site-packages/flask/app.py", line 872, in full_dispatch_request
    rv = self.handle_user_exception(e)
  File "/home/utm/portfo/venv/lib/python3.10/site-packages/flask_cors/extension.py", line 176, in wrapped_function
    return cors_after_request(app.make_response(f(*args, **kwargs)))
  File "/home/utm/portfo/venv/lib/python3.10/site-packages/flask/app.py", line 870, in full_dispatch_request
    rv = self.dispatch_request()
  File "/home/utm/portfo/venv/lib/python3.10/site-packages/flask/app.py", line 855, in dispatch_request
    return self.ensure_sync(self.view_functions[rule.endpoint])(**view_args)  # type: ignore[no-any-return]
  File "/home/utm/portfo/./portfo.py", line 225, in download_step1
    data = pd.read_json(url)
  File "/home/utm/portfo/venv/lib/python3.10/site-packages/pandas/io/json/_json.py", line 815, in read_json
    return json_reader.read()
  File "/home/utm/portfo/venv/lib/python3.10/site-packages/pandas/io/json/_json.py", line 1025, in read
    obj = self._get_object_parser(self.data)
  File "/home/utm/portfo/venv/lib/python3.10/site-packages/pandas/io/json/_json.py", line 1051, in _get_object_parser
    obj = FrameParser(json, **kwargs).parse()
  File "/home/utm/portfo/venv/lib/python3.10/site-packages/pandas/io/json/_json.py", line 1187, in parse
    self._parse()
  File "/home/utm/portfo/venv/lib/python3.10/site-packages/pandas/io/json/_json.py", line 1399, in _parse
    self.obj = DataFrame(
  File "/home/utm/portfo/venv/lib/python3.10/site-packages/pandas/core/frame.py", line 875, in __init__
    raise ValueError("DataFrame constructor not properly called!")
ValueError: DataFrame constructor not properly called!
2024-03-27 09:22:48,880 ERROR portfo uWSGIWorker1Core0 : Exception on /favicon.ico [GET]
Traceback (most recent call last):
  File "/home/utm/portfo/venv/lib/python3.10/site-packages/flask/app.py", line 1463, in wsgi_app
    response = self.full_dispatch_request()
  File "/home/utm/portfo/venv/lib/python3.10/site-packages/flask/app.py", line 872, in full_dispatch_request
    rv = self.handle_user_exception(e)
  File "/home/utm/portfo/venv/lib/python3.10/site-packages/flask_cors/extension.py", line 176, in wrapped_function
    return cors_after_request(app.make_response(f(*args, **kwargs)))
  File "/home/utm/portfo/venv/lib/python3.10/site-packages/flask/app.py", line 870, in full_dispatch_request
    rv = self.dispatch_request()
  File "/home/utm/portfo/venv/lib/python3.10/site-packages/flask/app.py", line 855, in dispatch_request
    return self.ensure_sync(self.view_functions[rule.endpoint])(**view_args)  # type: ignore[no-any-return]
  File "/home/utm/portfo/./portfo.py", line 61, in html_page
    return render_template(page_name)
  File "/home/utm/portfo/venv/lib/python3.10/site-packages/flask/templating.py", line 149, in render_template
    template = app.jinja_env.get_or_select_template(template_name_or_list)
  File "/home/utm/portfo/venv/lib/python3.10/site-packages/jinja2/environment.py", line 1081, in get_or_select_template
    return self.get_template(template_name_or_list, parent, globals)
  File "/home/utm/portfo/venv/lib/python3.10/site-packages/jinja2/environment.py", line 1010, in get_template
    return self._load_template(name, globals)
  File "/home/utm/portfo/venv/lib/python3.10/site-packages/jinja2/environment.py", line 969, in _load_template
    template = self.loader.load(self, name, self.make_globals(globals))
  File "/home/utm/portfo/venv/lib/python3.10/site-packages/jinja2/loaders.py", line 125, in load
    source, filename, uptodate = self.get_source(environment, name)
  File "/home/utm/portfo/venv/lib/python3.10/site-packages/flask/templating.py", line 65, in get_source
    return self._get_source_fast(environment, template)
  File "/home/utm/portfo/venv/lib/python3.10/site-packages/flask/templating.py", line 99, in _get_source_fast
    raise TemplateNotFound(template)
jinja2.exceptions.TemplateNotFound: favicon.ico
2024-03-27 09:26:17,958 INFO root uWSGIWorker1Core0 : JSON data saved successfully
2024-03-27 09:26:21,023 DEBUG urllib3.connectionpool uWSGIWorker4Core0 : Starting new HTTP connection (1): 161.111.137.92:8001
2024-03-27 09:26:21,025 DEBUG urllib3.connectionpool uWSGIWorker4Core0 : http://161.111.137.92:8001 "GET /static/csv/uploaded_data.json HTTP/1.1" 200 11072
2024-03-27 09:26:21,027 ERROR portfo uWSGIWorker4Core0 : Exception on /download_step1 [POST]
Traceback (most recent call last):
  File "/home/utm/portfo/venv/lib/python3.10/site-packages/flask/app.py", line 1463, in wsgi_app
    response = self.full_dispatch_request()
  File "/home/utm/portfo/venv/lib/python3.10/site-packages/flask/app.py", line 872, in full_dispatch_request
    rv = self.handle_user_exception(e)
  File "/home/utm/portfo/venv/lib/python3.10/site-packages/flask_cors/extension.py", line 176, in wrapped_function
    return cors_after_request(app.make_response(f(*args, **kwargs)))
  File "/home/utm/portfo/venv/lib/python3.10/site-packages/flask/app.py", line 870, in full_dispatch_request
    rv = self.dispatch_request()
  File "/home/utm/portfo/venv/lib/python3.10/site-packages/flask/app.py", line 855, in dispatch_request
    return self.ensure_sync(self.view_functions[rule.endpoint])(**view_args)  # type: ignore[no-any-return]
  File "/home/utm/portfo/./portfo.py", line 229, in download_step1
    df = pd.DataFrame(data)
  File "/home/utm/portfo/venv/lib/python3.10/site-packages/pandas/core/frame.py", line 875, in __init__
    raise ValueError("DataFrame constructor not properly called!")
ValueError: DataFrame constructor not properly called!
2024-03-27 09:26:21,133 ERROR portfo uWSGIWorker3Core0 : Exception on /favicon.ico [GET]
Traceback (most recent call last):
  File "/home/utm/portfo/venv/lib/python3.10/site-packages/flask/app.py", line 1463, in wsgi_app
    response = self.full_dispatch_request()
  File "/home/utm/portfo/venv/lib/python3.10/site-packages/flask/app.py", line 872, in full_dispatch_request
    rv = self.handle_user_exception(e)
  File "/home/utm/portfo/venv/lib/python3.10/site-packages/flask_cors/extension.py", line 176, in wrapped_function
    return cors_after_request(app.make_response(f(*args, **kwargs)))
  File "/home/utm/portfo/venv/lib/python3.10/site-packages/flask/app.py", line 870, in full_dispatch_request
    rv = self.dispatch_request()
  File "/home/utm/portfo/venv/lib/python3.10/site-packages/flask/app.py", line 855, in dispatch_request
    return self.ensure_sync(self.view_functions[rule.endpoint])(**view_args)  # type: ignore[no-any-return]
  File "/home/utm/portfo/./portfo.py", line 61, in html_page
    return render_template(page_name)
  File "/home/utm/portfo/venv/lib/python3.10/site-packages/flask/templating.py", line 149, in render_template
    template = app.jinja_env.get_or_select_template(template_name_or_list)
  File "/home/utm/portfo/venv/lib/python3.10/site-packages/jinja2/environment.py", line 1081, in get_or_select_template
    return self.get_template(template_name_or_list, parent, globals)
  File "/home/utm/portfo/venv/lib/python3.10/site-packages/jinja2/environment.py", line 1010, in get_template
    return self._load_template(name, globals)
  File "/home/utm/portfo/venv/lib/python3.10/site-packages/jinja2/environment.py", line 969, in _load_template
    template = self.loader.load(self, name, self.make_globals(globals))
  File "/home/utm/portfo/venv/lib/python3.10/site-packages/jinja2/loaders.py", line 125, in load
    source, filename, uptodate = self.get_source(environment, name)
  File "/home/utm/portfo/venv/lib/python3.10/site-packages/flask/templating.py", line 65, in get_source
    return self._get_source_fast(environment, template)
  File "/home/utm/portfo/venv/lib/python3.10/site-packages/flask/templating.py", line 99, in _get_source_fast
    raise TemplateNotFound(template)
jinja2.exceptions.TemplateNotFound: favicon.ico
2024-03-27 09:32:23,181 ERROR portfo uWSGIWorker4Core0 : Exception on /upload_json [POST]
Traceback (most recent call last):
  File "/home/utm/portfo/venv/lib/python3.10/site-packages/flask/app.py", line 1463, in wsgi_app
    response = self.full_dispatch_request()
  File "/home/utm/portfo/venv/lib/python3.10/site-packages/flask/app.py", line 872, in full_dispatch_request
    rv = self.handle_user_exception(e)
  File "/home/utm/portfo/venv/lib/python3.10/site-packages/flask_cors/extension.py", line 176, in wrapped_function
    return cors_after_request(app.make_response(f(*args, **kwargs)))
  File "/home/utm/portfo/venv/lib/python3.10/site-packages/flask/app.py", line 870, in full_dispatch_request
    rv = self.dispatch_request()
  File "/home/utm/portfo/venv/lib/python3.10/site-packages/flask/app.py", line 855, in dispatch_request
    return self.ensure_sync(self.view_functions[rule.endpoint])(**view_args)  # type: ignore[no-any-return]
  File "/home/utm/portfo/./portfo.py", line 306, in upload_json
    df = pd.DataFrame(json_data)
  File "/home/utm/portfo/venv/lib/python3.10/site-packages/pandas/core/frame.py", line 875, in __init__
    raise ValueError("DataFrame constructor not properly called!")
ValueError: DataFrame constructor not properly called!
2024-03-27 09:32:26,956 DEBUG urllib3.connectionpool uWSGIWorker4Core0 : Starting new HTTP connection (1): datahub.utm.csic.es:80
2024-03-27 09:32:27,172 DEBUG urllib3.connectionpool uWSGIWorker4Core0 : http://datahub.utm.csic.es:80 "GET /ws/getBBox/?id=sdg20240115 HTTP/1.1" 200 50
2024-03-27 09:37:39,268 ERROR portfo uWSGIWorker3Core0 : Exception on /upload_json [POST]
Traceback (most recent call last):
  File "/home/utm/portfo/venv/lib/python3.10/site-packages/flask/app.py", line 1463, in wsgi_app
    response = self.full_dispatch_request()
  File "/home/utm/portfo/venv/lib/python3.10/site-packages/flask/app.py", line 872, in full_dispatch_request
    rv = self.handle_user_exception(e)
  File "/home/utm/portfo/venv/lib/python3.10/site-packages/flask_cors/extension.py", line 176, in wrapped_function
    return cors_after_request(app.make_response(f(*args, **kwargs)))
  File "/home/utm/portfo/venv/lib/python3.10/site-packages/flask/app.py", line 870, in full_dispatch_request
    rv = self.dispatch_request()
  File "/home/utm/portfo/venv/lib/python3.10/site-packages/flask/app.py", line 855, in dispatch_request
    return self.ensure_sync(self.view_functions[rule.endpoint])(**view_args)  # type: ignore[no-any-return]
  File "/home/utm/portfo/./portfo.py", line 307, in upload_json
    df = pd.DataFrame(url)
  File "/home/utm/portfo/venv/lib/python3.10/site-packages/pandas/core/frame.py", line 875, in __init__
    raise ValueError("DataFrame constructor not properly called!")
ValueError: DataFrame constructor not properly called!
2024-03-27 09:37:42,784 DEBUG urllib3.connectionpool uWSGIWorker3Core0 : Starting new HTTP connection (1): datahub.utm.csic.es:80
2024-03-27 09:37:42,940 DEBUG urllib3.connectionpool uWSGIWorker3Core0 : http://datahub.utm.csic.es:80 "GET /ws/getBBox/?id=sdg20240115 HTTP/1.1" 200 50
2024-03-27 09:46:12,762 ERROR portfo uWSGIWorker1Core0 : Exception on /upload_json [POST]
Traceback (most recent call last):
  File "/home/utm/portfo/venv/lib/python3.10/site-packages/flask/app.py", line 1463, in wsgi_app
    response = self.full_dispatch_request()
  File "/home/utm/portfo/venv/lib/python3.10/site-packages/flask/app.py", line 872, in full_dispatch_request
    rv = self.handle_user_exception(e)
  File "/home/utm/portfo/venv/lib/python3.10/site-packages/flask_cors/extension.py", line 176, in wrapped_function
    return cors_after_request(app.make_response(f(*args, **kwargs)))
  File "/home/utm/portfo/venv/lib/python3.10/site-packages/flask/app.py", line 870, in full_dispatch_request
    rv = self.dispatch_request()
  File "/home/utm/portfo/venv/lib/python3.10/site-packages/flask/app.py", line 855, in dispatch_request
    return self.ensure_sync(self.view_functions[rule.endpoint])(**view_args)  # type: ignore[no-any-return]
  File "/home/utm/portfo/./portfo.py", line 317, in upload_json
    save_json_to_csv(json_data, filename)
  File "/home/utm/portfo/./portfo.py", line 300, in save_json_to_csv
    df = pd.DataFrame(json_data)
  File "/home/utm/portfo/venv/lib/python3.10/site-packages/pandas/core/frame.py", line 875, in __init__
    raise ValueError("DataFrame constructor not properly called!")
ValueError: DataFrame constructor not properly called!
2024-03-27 09:46:16,409 DEBUG urllib3.connectionpool uWSGIWorker3Core0 : Starting new HTTP connection (1): datahub.utm.csic.es:80
2024-03-27 09:46:16,444 DEBUG urllib3.connectionpool uWSGIWorker3Core0 : http://datahub.utm.csic.es:80 "GET /ws/getBBox/?id=sdg20240115 HTTP/1.1" 200 50
2024-03-27 09:51:27,511 ERROR portfo uWSGIWorker2Core0 : Exception on /upload_json [POST]
Traceback (most recent call last):
  File "/home/utm/portfo/venv/lib/python3.10/site-packages/flask/app.py", line 1463, in wsgi_app
    response = self.full_dispatch_request()
  File "/home/utm/portfo/venv/lib/python3.10/site-packages/flask/app.py", line 872, in full_dispatch_request
    rv = self.handle_user_exception(e)
  File "/home/utm/portfo/venv/lib/python3.10/site-packages/flask_cors/extension.py", line 176, in wrapped_function
    return cors_after_request(app.make_response(f(*args, **kwargs)))
  File "/home/utm/portfo/venv/lib/python3.10/site-packages/flask/app.py", line 870, in full_dispatch_request
    rv = self.dispatch_request()
  File "/home/utm/portfo/venv/lib/python3.10/site-packages/flask/app.py", line 855, in dispatch_request
    return self.ensure_sync(self.view_functions[rule.endpoint])(**view_args)  # type: ignore[no-any-return]
  File "/home/utm/portfo/./portfo.py", line 317, in upload_json
    save_json_to_csv(json_data, filename)
  File "/home/utm/portfo/./portfo.py", line 300, in save_json_to_csv
    df = pd.DataFrame(json_data)
  File "/home/utm/portfo/venv/lib/python3.10/site-packages/pandas/core/frame.py", line 875, in __init__
    raise ValueError("DataFrame constructor not properly called!")
ValueError: DataFrame constructor not properly called!
2024-03-27 09:51:34,219 DEBUG urllib3.connectionpool uWSGIWorker2Core0 : Starting new HTTP connection (1): datahub.utm.csic.es:80
2024-03-27 09:51:34,276 DEBUG urllib3.connectionpool uWSGIWorker2Core0 : http://datahub.utm.csic.es:80 "GET /ws/getBBox/?id=sdg20240115 HTTP/1.1" 200 50
2024-04-09 11:33:49,511 INFO werkzeug MainThread : [31m[1mWARNING: This is a development server. Do not use it in a production deployment. Use a production WSGI server instead.[0m
 * Running on all addresses (0.0.0.0)
 * Running on http://127.0.0.1:5000
 * Running on http://10.6.0.17:5000
2024-04-09 11:33:49,511 INFO werkzeug MainThread : [33mPress CTRL+C to quit[0m
